Referencia hard.xlsx ignorada por no tener suficientes columnas
Traceback (most recent call last):
  File "C:\Users\katejada\Desktop\Codigos y .Exe\ACH\cross3.py", line 150, in <module>
    raise ValueError("No se pudieron procesar archivos de referencia válidos.")
ValueError: No se pudieron procesar archivos de referencia válidos.
