Referencia hard.xlsx ignorada por no tener suficientes columnas
Traceback (most recent call last):
  File "C:\Users\katejada\Desktop\Codigos y .Exe\ACH\cross3.py", line 150, in <module>
    raise ValueError("No se pudieron procesar archivos de referencia v치lidos.")
ValueError: No se pudieron procesar archivos de referencia v치lidos.


error 2 
Error procesando referencia hard.xlsx: Unencrypted document
Traceback (most recent call last):
  File "C:\Users\katejada\Desktop\Codigos y .Exe\ACH\cross3.py", line 195, in <module>
    raise ValueError("No se pudieron procesar archivos de referencia v치lidos.")
ValueError: No se pudieron procesar archivos de referencia v치lidos.
